Workbook

Sheet Portfolio Guide
A1: PLAN | KIND INSIGHTS
A4: Commercial Energy Project Price Estimator
A7: FINANCIAL MODELING · SCENARIO ANALYSIS · ENERGY POLICY
A9: PURPOSE | B9: PURPOSE | C9: Organizes component costs and benchmark estimates to support early-stage comparison of commercial and utility-scale energy projects. | D9: Organizes component costs and benchmark estimates to support early-stage comparison of commercial and utility-scale energy projects. | E9: Organizes component costs and benchmark estimates to support early-stage comparison of commercial and utility-scale energy projects. | F9: Organizes component costs and benchmark estimates to support early-stage comparison of commercial and utility-scale energy projects. | G9: Organizes component costs and benchmark estimates to support early-stage comparison of commercial and utility-scale energy projects. | H9: Organizes component costs and benchmark estimates to support early-stage comparison of commercial and utility-scale energy projects.
C10: Organizes component costs and benchmark estimates to support early-stage comparison of commercial and utility-scale energy projects. | D10: Organizes component costs and benchmark estimates to support early-stage comparison of commercial and utility-scale energy projects. | E10: Organizes component costs and benchmark estimates to support early-stage comparison of commercial and utility-scale energy projects. | F10: Organizes component costs and benchmark estimates to support early-stage comparison of commercial and utility-scale energy projects. | G10: Organizes component costs and benchmark estimates to support early-stage comparison of commercial and utility-scale energy projects. | H10: Organizes component costs and benchmark estimates to support early-stage comparison of commercial and utility-scale energy projects.
C11: Organizes component costs and benchmark estimates to support early-stage comparison of commercial and utility-scale energy projects. | D11: Organizes component costs and benchmark estimates to support early-stage comparison of commercial and utility-scale energy projects. | E11: Organizes component costs and benchmark estimates to support early-stage comparison of commercial and utility-scale energy projects. | F11: Organizes component costs and benchmark estimates to support early-stage comparison of commercial and utility-scale energy projects. | G11: Organizes component costs and benchmark estimates to support early-stage comparison of commercial and utility-scale energy projects. | H11: Organizes component costs and benchmark estimates to support early-stage comparison of commercial and utility-scale energy projects.
A13: HOW TO USE | B13: HOW TO USE | C13: Review the Cost Calculator and scenario sheets. Confirm all assumptions before using outputs for planning. | D13: Review the Cost Calculator and scenario sheets. Confirm all assumptions before using outputs for planning. | E13: Review the Cost Calculator and scenario sheets. Confirm all assumptions before using outputs for planning. | F13: Review the Cost Calculator and scenario sheets. Confirm all assumptions before using outputs for planning. | G13: Review the Cost Calculator and scenario sheets. Confirm all assumptions before using outputs for planning. | H13: Review the Cost Calculator and scenario sheets. Confirm all assumptions before using outputs for planning.
C14: Review the Cost Calculator and scenario sheets. Confirm all assumptions before using outputs for planning. | D14: Review the Cost Calculator and scenario sheets. Confirm all assumptions before using outputs for planning. | E14: Review the Cost Calculator and scenario sheets. Confirm all assumptions before using outputs for planning. | F14: Review the Cost Calculator and scenario sheets. Confirm all assumptions before using outputs for planning. | G14: Review the Cost Calculator and scenario sheets. Confirm all assumptions before using outputs for planning. | H14: Review the Cost Calculator and scenario sheets. Confirm all assumptions before using outputs for planning.
C15: Review the Cost Calculator and scenario sheets. Confirm all assumptions before using outputs for planning. | D15: Review the Cost Calculator and scenario sheets. Confirm all assumptions before using outputs for planning. | E15: Review the Cost Calculator and scenario sheets. Confirm all assumptions before using outputs for planning. | F15: Review the Cost Calculator and scenario sheets. Confirm all assumptions before using outputs for planning. | G15: Review the Cost Calculator and scenario sheets. Confirm all assumptions before using outputs for planning. | H15: Review the Cost Calculator and scenario sheets. Confirm all assumptions before using outputs for planning.
A17: IMPORTANT | B17: IMPORTANT | C17: Portfolio copy of a planning model. Estimates are not bids, engineering designs, or investment advice. | D17: Portfolio copy of a planning model. Estimates are not bids, engineering designs, or investment advice. | E17: Portfolio copy of a planning model. Estimates are not bids, engineering designs, or investment advice. | F17: Portfolio copy of a planning model. Estimates are not bids, engineering designs, or investment advice. | G17: Portfolio copy of a planning model. Estimates are not bids, engineering designs, or investment advice. | H17: Portfolio copy of a planning model. Estimates are not bids, engineering designs, or investment advice.
C18: Portfolio copy of a planning model. Estimates are not bids, engineering designs, or investment advice. | D18: Portfolio copy of a planning model. Estimates are not bids, engineering designs, or investment advice. | E18: Portfolio copy of a planning model. Estimates are not bids, engineering designs, or investment advice. | F18: Portfolio copy of a planning model. Estimates are not bids, engineering designs, or investment advice. | G18: Portfolio copy of a planning model. Estimates are not bids, engineering designs, or investment advice. | H18: Portfolio copy of a planning model. Estimates are not bids, engineering designs, or investment advice.
C19: Portfolio copy of a planning model. Estimates are not bids, engineering designs, or investment advice. | D19: Portfolio copy of a planning model. Estimates are not bids, engineering designs, or investment advice. | E19: Portfolio copy of a planning model. Estimates are not bids, engineering designs, or investment advice. | F19: Portfolio copy of a planning model. Estimates are not bids, engineering designs, or investment advice. | G19: Portfolio copy of a planning model. Estimates are not bids, engineering designs, or investment advice. | H19: Portfolio copy of a planning model. Estimates are not bids, engineering designs, or investment advice.
C20: Portfolio copy of a planning model. Estimates are not bids, engineering designs, or investment advice. | D20: Portfolio copy of a planning model. Estimates are not bids, engineering designs, or investment advice. | E20: Portfolio copy of a planning model. Estimates are not bids, engineering designs, or investment advice. | F20: Portfolio copy of a planning model. Estimates are not bids, engineering designs, or investment advice. | G20: Portfolio copy of a planning model. Estimates are not bids, engineering designs, or investment advice. | H20: Portfolio copy of a planning model. Estimates are not bids, engineering designs, or investment advice.
A22: PORTFOLIO NOTE | B22: PORTFOLIO NOTE | C22: This workbook is a cleaned presentation copy of prior analytical work. Core calculations and substantive content have not been rewritten. | D22: This workbook is a cleaned presentation copy of prior analytical work. Core calculations and substantive content have not been rewritten. | E22: This workbook is a cleaned presentation copy of prior analytical work. Core calculations and substantive content have not been rewritten. | F22: This workbook is a cleaned presentation copy of prior analytical work. Core calculations and substantive content have not been rewritten. | G22: This workbook is a cleaned presentation copy of prior analytical work. Core calculations and substantive content have not been rewritten. | H22: This workbook is a cleaned presentation copy of prior analytical work. Core calculations and substantive content have not been rewritten.
C23: This workbook is a cleaned presentation copy of prior analytical work. Core calculations and substantive content have not been rewritten. | D23: This workbook is a cleaned presentation copy of prior analytical work. Core calculations and substantive content have not been rewritten. | E23: This workbook is a cleaned presentation copy of prior analytical work. Core calculations and substantive content have not been rewritten. | F23: This workbook is a cleaned presentation copy of prior analytical work. Core calculations and substantive content have not been rewritten. | G23: This workbook is a cleaned presentation copy of prior analytical work. Core calculations and substantive content have not been rewritten. | H23: This workbook is a cleaned presentation copy of prior analytical work. Core calculations and substantive content have not been rewritten.
C24: This workbook is a cleaned presentation copy of prior analytical work. Core calculations and substantive content have not been rewritten. | D24: This workbook is a cleaned presentation copy of prior analytical work. Core calculations and substantive content have not been rewritten. | E24: This workbook is a cleaned presentation copy of prior analytical work. Core calculations and substantive content have not been rewritten. | F24: This workbook is a cleaned presentation copy of prior analytical work. Core calculations and substantive content have not been rewritten. | G24: This workbook is a cleaned presentation copy of prior analytical work. Core calculations and substantive content have not been rewritten. | H24: This workbook is a cleaned presentation copy of prior analytical work. Core calculations and substantive content have not been rewritten.
A26: Grounded in evidence. Focused on impact.

Sheet Public Library Cost
A1: Pearl City Public Library
A2: PV, BESS, EV Installation Alone
A3: PV, BESS, EV
A4: Equipment | B4: 411192
A5: Labor | B5: 616788
A6: Subtotal | B6: =SUM(B4:B5) -> 1027980
A7: Sub contractor JOOH (10%) | B7: =B6*0.1 -> 102798
A8: Subcontractor HOOH (10.2%) | B8: =(B6+B7)*0.102 -> 115339.36
A9: Subcontractor Profit (10%) | B9: =(B8+B7+B6)*0.1 -> 124611.74
A10: Total | B10: =SUM(B6:B9) -> 1370729.1
A12: Cost Breakdown
A13: PV Costs | B13: =B10 -> 1370729.1
A14: Structural Costs | B14: 363398
A15: Archictectural Costs | B15: 78695
A16: Escalation to Midpoint of Construction | B16: =SUM(B13:B15)*0.053 -> 96079.571
A17: Design Contingency | B17: =SUM(B13:B16)*0.15 -> 286335.25
A18: Markups
A19: Prime Contractor JOOH | B19: =SUM(B13:B17)*0.15 -> 329285.54
A20: Prime Contracto HOOH | B20: =SUM(B13:B17,B19)*0.051 -> 128750.64
A21: Prime Contractor Profit | B21: =SUM(B13:B17,B19,B20)*0.06 -> 159196.39
A22: Bond | B22: =SUM(B13:B17,B19,B20,B21)*0.015 -> 42187.042
A23: G.E. Tax | B23: =SUM(B13:B22)*0.04712 -> 134511.42
A24: Total | B24: =SUM(B13:B23) -> 2989167.9
A28: Further

Sheet Cost Calculator
D1: * No Land Costs Included
B2: Type of Installation | C2: Commercial
B3: Battery Storage (4 hr. for Utility, 2 hr. for Commercial) | C3: PV + BESS
B4: Installation Size (MW) (If Battery only, size is MW) | C4: 10
B5: Total Project Costs | C5: =SUMIF(A9:A41,"Yes",C9:C41)/COUNTIF(A9:A41,"Yes")*C4*1000000 -> 1.006769e+08
A7: Select Similar Projects for your Estimate | C7: Project Specific Information | H7: Anticipated Project Cost Breakdowns
A8: Select similar projects to include in calculation | B8: Project Costs are currently aggregated (PV & Battery together) Some projects may have different sized batteries | C8: $/W | D8: Installation Size (MW) | E8: Year Installed | F8: Storage Included | H8: Cost Breakdown Components | I8: Dollar Expenditures | J8: Percent of Total Costs
A9: No | B9: =IF($C$2="Utility-Scale",'Utility Scale Estimates'!B2,IF($C$2="Commercial",'Commercial Scale & UHManoa PV'!B8,"")) -> Gateway House | C9: =IF($C$2="Utility-Scale",'Utility Scale Estimates'!C2,IF($C$2="Commercial",'Commercial Scale & UHManoa PV'!G8,"")) -> 3.5593793 | D9: =IF($C$2="Utility-Scale",'Utility Scale Estimates'!E2,IF($C$2="Commercial",'Commercial Scale & UHManoa PV'!C8/1000,"")) -> 0.029 | E9: =IF($C$2="Utility-Scale",'Utility Scale Estimates'!F2,IF($C$2="Commercial",'Commercial Scale & UHManoa PV'!E8,"")) -> 2023 | F9: =IF($C$2="Utility-Scale",'Utility Scale Estimates'!G2,IF($C$2="Commercial",'Commercial Scale & UHManoa PV'!D8,"")) -> No | H9: =IF($C$2="Utility-Scale", 'Output Charts Breakdown'!A3, IF($C$2="Commercial", 'Output Charts Breakdown'!E3, )) -> Engineering, Procurement, Construction /Developer Net Profit | I9: =IF($C$2="Utility-Scale", 'Output Charts Breakdown'!B3, IF($C$2="Commercial", 'Output Charts Breakdown'!F3, )) -> 7467666.6 | J9: =IF($C$2="Utility-Scale", 'Output Charts Breakdown'!C3, IF($C$2="Commercial", 'Output Charts Breakdown'!G3, )) -> 0.074174582
A10: No | B10: =IF($C$2="Utility-Scale",'Utility Scale Estimates'!B3,IF($C$2="Commercial",'Commercial Scale & UHManoa PV'!B9,"")) -> Frear Hall | C10: =IF($C$2="Utility-Scale",'Utility Scale Estimates'!C3,IF($C$2="Commercial",'Commercial Scale & UHManoa PV'!G9,"")) -> 3.535 | D10: =IF($C$2="Utility-Scale",'Utility Scale Estimates'!E3,IF($C$2="Commercial",'Commercial Scale & UHManoa PV'!C9/1000,"")) -> 0.047 | E10: =IF($C$2="Utility-Scale",'Utility Scale Estimates'!F3,IF($C$2="Commercial",'Commercial Scale & UHManoa PV'!E9,"")) -> 2023 | F10: =IF($C$2="Utility-Scale",'Utility Scale Estimates'!G3,IF($C$2="Commercial",'Commercial Scale & UHManoa PV'!D9,"")) -> No | H10: =IF($C$2="Utility-Scale", 'Output Charts Breakdown'!A4, IF($C$2="Commercial", 'Output Charts Breakdown'!E4, )) -> Developer Overhead | I10: =IF($C$2="Utility-Scale", 'Output Charts Breakdown'!B4, IF($C$2="Commercial", 'Output Charts Breakdown'!F4, )) -> 2641004 | J10: =IF($C$2="Utility-Scale", 'Output Charts Breakdown'!C4, IF($C$2="Commercial", 'Output Charts Breakdown'!G4, )) -> 0.026232474
A11: No | B11: =IF($C$2="Utility-Scale",'Utility Scale Estimates'!B4,IF($C$2="Commercial",'Commercial Scale & UHManoa PV'!B10,"")) -> Gyms 1&2 | C11: =IF($C$2="Utility-Scale",'Utility Scale Estimates'!C4,IF($C$2="Commercial",'Commercial Scale & UHManoa PV'!G10,"")) -> 5.05 | D11: =IF($C$2="Utility-Scale",'Utility Scale Estimates'!E4,IF($C$2="Commercial",'Commercial Scale & UHManoa PV'!C10/1000,"")) -> 0.324 | E11: =IF($C$2="Utility-Scale",'Utility Scale Estimates'!F4,IF($C$2="Commercial",'Commercial Scale & UHManoa PV'!E10,"")) -> 2023 | F11: =IF($C$2="Utility-Scale",'Utility Scale Estimates'!G4,IF($C$2="Commercial",'Commercial Scale & UHManoa PV'!D10,"")) -> No | H11: =IF($C$2="Utility-Scale", 'Output Charts Breakdown'!A5, IF($C$2="Commercial", 'Output Charts Breakdown'!E5, )) -> Contingency | I11: =IF($C$2="Utility-Scale", 'Output Charts Breakdown'!B5, IF($C$2="Commercial", 'Output Charts Breakdown'!F5, )) -> 2641004 | J11: =IF($C$2="Utility-Scale", 'Output Charts Breakdown'!C5, IF($C$2="Commercial", 'Output Charts Breakdown'!G5, )) -> 0.026232474
A12: No | B12: =IF($C$2="Utility-Scale",'Utility Scale Estimates'!B5,IF($C$2="Commercial",'Commercial Scale & UHManoa PV'!B11,"")) -> John Burns Hall | C12: =IF($C$2="Utility-Scale",'Utility Scale Estimates'!C5,IF($C$2="Commercial",'Commercial Scale & UHManoa PV'!G11,"")) -> 5.05 | D12: =IF($C$2="Utility-Scale",'Utility Scale Estimates'!E5,IF($C$2="Commercial",'Commercial Scale & UHManoa PV'!C11/1000,"")) -> 0.18 | E12: =IF($C$2="Utility-Scale",'Utility Scale Estimates'!F5,IF($C$2="Commercial",'Commercial Scale & UHManoa PV'!E11,"")) -> 2011 | F12: =IF($C$2="Utility-Scale",'Utility Scale Estimates'!G5,IF($C$2="Commercial",'Commercial Scale & UHManoa PV'!D11,"")) -> No | H12: =IF($C$2="Utility-Scale", 'Output Charts Breakdown'!A6, IF($C$2="Commercial", 'Output Charts Breakdown'!E6, )) -> Transmission Line | I12: =IF($C$2="Utility-Scale", 'Output Charts Breakdown'!B6, IF($C$2="Commercial", 'Output Charts Breakdown'!F6, )) -> 0 | J12: =IF($C$2="Utility-Scale", 'Output Charts Breakdown'!C6, IF($C$2="Commercial", 'Output Charts Breakdown'!G6, )) -> 0
A13: No | B13: =IF($C$2="Utility-Scale",'Utility Scale Estimates'!B6,IF($C$2="Commercial",'Commercial Scale & UHManoa PV'!B12,"")) -> Gartley Hall | C13: =IF($C$2="Utility-Scale",'Utility Scale Estimates'!C6,IF($C$2="Commercial",'Commercial Scale & UHManoa PV'!G12,"")) -> 5.05 | D13: =IF($C$2="Utility-Scale",'Utility Scale Estimates'!E6,IF($C$2="Commercial",'Commercial Scale & UHManoa PV'!C12/1000,"")) -> 0.045 | E13: =IF($C$2="Utility-Scale",'Utility Scale Estimates'!F6,IF($C$2="Commercial",'Commercial Scale & UHManoa PV'!E12,"")) -> 2014 | F13: =IF($C$2="Utility-Scale",'Utility Scale Estimates'!G6,IF($C$2="Commercial",'Commercial Scale & UHManoa PV'!D12,"")) -> No | H13: =IF($C$2="Utility-Scale", 'Output Charts Breakdown'!A7, IF($C$2="Commercial", 'Output Charts Breakdown'!E7, )) -> Interconnection Fee | I13: =IF($C$2="Utility-Scale", 'Output Charts Breakdown'!B7, IF($C$2="Commercial", 'Output Charts Breakdown'!F7, )) -> 1274967.5 | J13: =IF($C$2="Utility-Scale", 'Output Charts Breakdown'!C7, IF($C$2="Commercial", 'Output Charts Breakdown'!G7, )) -> 0.012663953
A14: No | B14: =IF($C$2="Utility-Scale",'Utility Scale Estimates'!B7,IF($C$2="Commercial",'Commercial Scale & UHManoa PV'!B13,"")) -> Holmes Hall | C14: =IF($C$2="Utility-Scale",'Utility Scale Estimates'!C7,IF($C$2="Commercial",'Commercial Scale & UHManoa PV'!G13,"")) -> 5.0500592 | D14: =IF($C$2="Utility-Scale",'Utility Scale Estimates'!E7,IF($C$2="Commercial",'Commercial Scale & UHManoa PV'!C13/1000,"")) -> 0.00845 | E14: =IF($C$2="Utility-Scale",'Utility Scale Estimates'!F7,IF($C$2="Commercial",'Commercial Scale & UHManoa PV'!E13,"")) -> 2013 | F14: =IF($C$2="Utility-Scale",'Utility Scale Estimates'!G7,IF($C$2="Commercial",'Commercial Scale & UHManoa PV'!D13,"")) -> No | H14: =IF($C$2="Utility-Scale", 'Output Charts Breakdown'!A8, IF($C$2="Commercial", 'Output Charts Breakdown'!E8, )) -> Permitting Fee | I14: =IF($C$2="Utility-Scale", 'Output Charts Breakdown'!B8, IF($C$2="Commercial", 'Output Charts Breakdown'!F8, )) -> 318741.87 | J14: =IF($C$2="Utility-Scale", 'Output Charts Breakdown'!C8, IF($C$2="Commercial", 'Output Charts Breakdown'!G8, )) -> 0.0031659882
A15: No | B15: =IF($C$2="Utility-Scale",'Utility Scale Estimates'!B8,IF($C$2="Commercial",'Commercial Scale & UHManoa PV'!B14,"")) -> Sinclair Library | C15: =IF($C$2="Utility-Scale",'Utility Scale Estimates'!C8,IF($C$2="Commercial",'Commercial Scale & UHManoa PV'!G14,"")) -> 5.2155738 | D15: =IF($C$2="Utility-Scale",'Utility Scale Estimates'!E8,IF($C$2="Commercial",'Commercial Scale & UHManoa PV'!C14/1000,"")) -> 0.0305 | E15: =IF($C$2="Utility-Scale",'Utility Scale Estimates'!F8,IF($C$2="Commercial",'Commercial Scale & UHManoa PV'!E14,"")) -> 2012 | F15: =IF($C$2="Utility-Scale",'Utility Scale Estimates'!G8,IF($C$2="Commercial",'Commercial Scale & UHManoa PV'!D14,"")) -> No | H15: =IF($C$2="Utility-Scale", 'Output Charts Breakdown'!A9, IF($C$2="Commercial", 'Output Charts Breakdown'!E9, )) -> Land Acquisition | I15: =IF($C$2="Utility-Scale", 'Output Charts Breakdown'!B9, IF($C$2="Commercial", 'Output Charts Breakdown'!F9, )) -> 0 | J15: =IF($C$2="Utility-Scale", 'Output Charts Breakdown'!C9, IF($C$2="Commercial", 'Output Charts Breakdown'!G9, )) -> 0
A16: No | B16: =IF($C$2="Utility-Scale",'Utility Scale Estimates'!B9,IF($C$2="Commercial",'Commercial Scale & UHManoa PV'!B15,"")) -> Warrior Recreation | C16: =IF($C$2="Utility-Scale",'Utility Scale Estimates'!C9,IF($C$2="Commercial",'Commercial Scale & UHManoa PV'!G15,"")) -> 5.05 | D16: =IF($C$2="Utility-Scale",'Utility Scale Estimates'!E9,IF($C$2="Commercial",'Commercial Scale & UHManoa PV'!C15/1000,"")) -> 0.033 | E16: =IF($C$2="Utility-Scale",'Utility Scale Estimates'!F9,IF($C$2="Commercial",'Commercial Scale & UHManoa PV'!E15,"")) -> 2013 | F16: =IF($C$2="Utility-Scale",'Utility Scale Estimates'!G9,IF($C$2="Commercial",'Commercial Scale & UHManoa PV'!D15,"")) -> No | H16: =IF($C$2="Utility-Scale", 'Output Charts Breakdown'!A10, IF($C$2="Commercial", 'Output Charts Breakdown'!E10, )) -> Sale Tax | I16: =IF($C$2="Utility-Scale", 'Output Charts Breakdown'!B10, IF($C$2="Commercial", 'Output Charts Breakdown'!F10, )) -> 4280247.9 | J16: =IF($C$2="Utility-Scale", 'Output Charts Breakdown'!C10, IF($C$2="Commercial", 'Output Charts Breakdown'!G10, )) -> 0.042514699
A17: No | B17: =IF($C$2="Utility-Scale",'Utility Scale Estimates'!B10,IF($C$2="Commercial",'Commercial Scale & UHManoa PV'!B16,"")) -> FROG Buildings | C17: =IF($C$2="Utility-Scale",'Utility Scale Estimates'!C10,IF($C$2="Commercial",'Commercial Scale & UHManoa PV'!G16,"")) -> 5.05 | D17: =IF($C$2="Utility-Scale",'Utility Scale Estimates'!E10,IF($C$2="Commercial",'Commercial Scale & UHManoa PV'!C16/1000,"")) -> 0.01612 | E17: =IF($C$2="Utility-Scale",'Utility Scale Estimates'!F10,IF($C$2="Commercial",'Commercial Scale & UHManoa PV'!E16,"")) -> 2018 | F17: =IF($C$2="Utility-Scale",'Utility Scale Estimates'!G10,IF($C$2="Commercial",'Commercial Scale & UHManoa PV'!D16,"")) -> No | H17: =IF($C$2="Utility-Scale", 'Output Charts Breakdown'!A11, IF($C$2="Commercial", 'Output Charts Breakdown'!E11, )) -> EPC Overhead | I17: =IF($C$2="Utility-Scale", 'Output Charts Breakdown'!B11, IF($C$2="Commercial", 'Output Charts Breakdown'!F11, )) -> 8105150.4 | J17: =IF($C$2="Utility-Scale", 'Output Charts Breakdown'!C11, IF($C$2="Commercial", 'Output Charts Breakdown'!G11, )) -> 0.080506558
A18: No | B18: =IF($C$2="Utility-Scale",'Utility Scale Estimates'!B11,IF($C$2="Commercial",'Commercial Scale & UHManoa PV'!B17,"")) -> PBRC | C18: =IF($C$2="Utility-Scale",'Utility Scale Estimates'!C11,IF($C$2="Commercial",'Commercial Scale & UHManoa PV'!G17,"")) -> 5.0500138 | D18: =IF($C$2="Utility-Scale",'Utility Scale Estimates'!E11,IF($C$2="Commercial",'Commercial Scale & UHManoa PV'!C17/1000,"")) -> 0.03619 | E18: =IF($C$2="Utility-Scale",'Utility Scale Estimates'!F11,IF($C$2="Commercial",'Commercial Scale & UHManoa PV'!E17,"")) -> 2012 | F18: =IF($C$2="Utility-Scale",'Utility Scale Estimates'!G11,IF($C$2="Commercial",'Commercial Scale & UHManoa PV'!D17,"")) -> No | H18: =IF($C$2="Utility-Scale", 'Output Charts Breakdown'!A12, IF($C$2="Commercial", 'Output Charts Breakdown'!E12, )) -> Install labor & Equipment | I18: =IF($C$2="Utility-Scale", 'Output Charts Breakdown'!B12, IF($C$2="Commercial", 'Output Charts Breakdown'!F12, )) -> 14343384 | J18: =IF($C$2="Utility-Scale", 'Output Charts Breakdown'!C12, IF($C$2="Commercial", 'Output Charts Breakdown'!G12, )) -> 0.14246947
A19: No | B19: =IF($C$2="Utility-Scale",'Utility Scale Estimates'!B12,IF($C$2="Commercial",'Commercial Scale & UHManoa PV'!B18,"")) -> Dance Building | C19: =IF($C$2="Utility-Scale",'Utility Scale Estimates'!C12,IF($C$2="Commercial",'Commercial Scale & UHManoa PV'!G18,"")) -> 5.0591818 | D19: =IF($C$2="Utility-Scale",'Utility Scale Estimates'!E12,IF($C$2="Commercial",'Commercial Scale & UHManoa PV'!C18/1000,"")) -> 0.011 | E19: =IF($C$2="Utility-Scale",'Utility Scale Estimates'!F12,IF($C$2="Commercial",'Commercial Scale & UHManoa PV'!E18,"")) -> 2023 | F19: =IF($C$2="Utility-Scale",'Utility Scale Estimates'!G12,IF($C$2="Commercial",'Commercial Scale & UHManoa PV'!D18,"")) -> No | H19: =IF($C$2="Utility-Scale", 'Output Charts Breakdown'!A13, IF($C$2="Commercial", 'Output Charts Breakdown'!E13, )) -> Electrical BOS | I19: =IF($C$2="Utility-Scale", 'Output Charts Breakdown'!B13, IF($C$2="Commercial", 'Output Charts Breakdown'!F13, )) -> 10063136 | J19: =IF($C$2="Utility-Scale", 'Output Charts Breakdown'!C13, IF($C$2="Commercial", 'Output Charts Breakdown'!G13, )) -> 0.099954772
A20: No | B20: =IF($C$2="Utility-Scale",'Utility Scale Estimates'!B13,IF($C$2="Commercial",'Commercial Scale & UHManoa PV'!B19,"")) -> Cancer Center (Freezer Facility) | C20: =IF($C$2="Utility-Scale",'Utility Scale Estimates'!C13,IF($C$2="Commercial",'Commercial Scale & UHManoa PV'!G19,"")) -> 4.949 | D20: =IF($C$2="Utility-Scale",'Utility Scale Estimates'!E13,IF($C$2="Commercial",'Commercial Scale & UHManoa PV'!C19/1000,"")) -> 0.015 | E20: =IF($C$2="Utility-Scale",'Utility Scale Estimates'!F13,IF($C$2="Commercial",'Commercial Scale & UHManoa PV'!E19,"")) -> 2023 | F20: =IF($C$2="Utility-Scale",'Utility Scale Estimates'!G13,IF($C$2="Commercial",'Commercial Scale & UHManoa PV'!D19,"")) -> No | H20: =IF($C$2="Utility-Scale", 'Output Charts Breakdown'!A14, IF($C$2="Commercial", 'Output Charts Breakdown'!E14, )) -> Structural BOS | I20: =IF($C$2="Utility-Scale", 'Output Charts Breakdown'!B14, IF($C$2="Commercial", 'Output Charts Breakdown'!F14, )) -> 8423892.2 | J20: =IF($C$2="Utility-Scale", 'Output Charts Breakdown'!C14, IF($C$2="Commercial", 'Output Charts Breakdown'!G14, )) -> 0.083672546
... A25: No | B25: =IF($C$2="Utility-Scale",'Utility Scale Estimates'!B18,IF($C$2="Commercial",'Commercial Scale & UHManoa PV'!B24,"")) -> Johnson Hall A | C25: =IF($C$2="Utility-Scale",'Utility Scale Estimates'!C18,IF($C$2="Commercial",'Commercial Scale & UHManoa PV'!G24,"")) -> 8.6336038 | D25: =IF($C$2="Utility-Scale",'Utility Scale Estimates'!E18,IF($C$2="Commercial",'Commercial Scale & UHManoa PV'!C24/1000,"")) -> 0.053 | E25: =IF($C$2="Utility-Scale",'Utility Scale Estimates'!F18,IF($C$2="Commercial",'Commercial Scale & UHManoa PV'!E24,"")) -> 2023 | F25: =IF($C$2="Utility-Scale",'Utility Scale Estimates'!G18,IF($C$2="Commercial",'Commercial Scale & UHManoa PV'!D24,"")) -> No | H25: =IF($C$2="Utility-Scale", 'Output Charts Breakdown'!A19, IF($C$2="Commercial", 'Output Charts Breakdown'!E19, )) -> Total | I25: =IF($C$2="Utility-Scale", 'Output Charts Breakdown'!B19, IF($C$2="Commercial", 'Output Charts Breakdown'!F19, )) -> 1.006769e+08 | J25: =IF($C$2="Utility-Scale", 'Output Charts Breakdown'!C19, IF($C$2="Commercial", 'Output Charts Breakdown'!G19, )) -> 1
A26: No | B26: =IF($C$2="Utility-Scale",'Utility Scale Estimates'!B19,IF($C$2="Commercial",'Commercial Scale & UHManoa PV'!B25,"")) -> Johnson Hall B | C26: =IF($C$2="Utility-Scale",'Utility Scale Estimates'!C19,IF($C$2="Commercial",'Commercial Scale & UHManoa PV'!G25,"")) -> 8.585 | D26: =IF($C$2="Utility-Scale",'Utility Scale Estimates'!E19,IF($C$2="Commercial",'Commercial Scale & UHManoa PV'!C25/1000,"")) -> 0.059 | E26: =IF($C$2="Utility-Scale",'Utility Scale Estimates'!F19,IF($C$2="Commercial",'Commercial Scale & UHManoa PV'!E25,"")) -> 2023 | F26: =IF($C$2="Utility-Scale",'Utility Scale Estimates'!G19,IF($C$2="Commercial",'Commercial Scale & UHManoa PV'!D25,"")) -> No
A27: No | B27: =IF($C$2="Utility-Scale",'Utility Scale Estimates'!B20,IF($C$2="Commercial",'Commercial Scale & UHManoa PV'!B26,"")) -> Architecrutre Building | C27: =IF($C$2="Utility-Scale",'Utility Scale Estimates'!C20,IF($C$2="Commercial",'Commercial Scale & UHManoa PV'!G26,"")) -> 8.585 | D27: =IF($C$2="Utility-Scale",'Utility Scale Estimates'!E20,IF($C$2="Commercial",'Commercial Scale & UHManoa PV'!C26/1000,"")) -> 0.226 | E27: =IF($C$2="Utility-Scale",'Utility Scale Estimates'!F20,IF($C$2="Commercial",'Commercial Scale & UHManoa PV'!E26,"")) -> 2023 | F27: =IF($C$2="Utility-Scale",'Utility Scale Estimates'!G20,IF($C$2="Commercial",'Commercial Scale & UHManoa PV'!D26,"")) -> No
A28: No | B28: =IF($C$2="Utility-Scale",'Utility Scale Estimates'!B21,IF($C$2="Commercial",'Commercial Scale & UHManoa PV'!B27,"")) -> Inouye Center | C28: =IF($C$2="Utility-Scale",'Utility Scale Estimates'!C21,IF($C$2="Commercial",'Commercial Scale & UHManoa PV'!G27,"")) -> 5.05 | D28: =IF($C$2="Utility-Scale",'Utility Scale Estimates'!E21,IF($C$2="Commercial",'Commercial Scale & UHManoa PV'!C27/1000,"")) -> 0.07 | E28: =IF($C$2="Utility-Scale",'Utility Scale Estimates'!F21,IF($C$2="Commercial",'Commercial Scale & UHManoa PV'!E27,"")) -> 2023 | F28: =IF($C$2="Utility-Scale",'Utility Scale Estimates'!G21,IF($C$2="Commercial",'Commercial Scale & UHManoa PV'!D27,"")) -> No
A29: No | B29: =IF($C$2="Utility-Scale",'Utility Scale Estimates'!B22,IF($C$2="Commercial",'Commercial Scale & UHManoa PV'!B28,"")) -> Law Library | C29: =IF($C$2="Utility-Scale",'Utility Scale Estimates'!C22,IF($C$2="Commercial",'Commercial Scale & UHManoa PV'!G28,"")) -> 8.585 | D29: =IF($C$2="Utility-Scale",'Utility Scale Estimates'!E22,IF($C$2="Commercial",'Commercial Scale & UHManoa PV'!C28/1000,"")) -> 0.508 | E29: =IF($C$2="Utility-Scale",'Utility Scale Estimates'!F22,IF($C$2="Commercial",'Commercial Scale & UHManoa PV'!E28,"")) -> 2023 | F29: =IF($C$2="Utility-Scale",'Utility Scale Estimates'!G22,IF($C$2="Commercial",'Commercial Scale & UHManoa PV'!D28,"")) -> No
A30: No | B30: =IF($C$2="Utility-Scale",'Utility Scale Estimates'!B23,IF($C$2="Commercial",'Commercial Scale & UHManoa PV'!B29,"")) -> Sakamaki Hall | C30: =IF($C$2="Utility-Scale",'Utility Scale Estimates'!C23,IF($C$2="Commercial",'Commercial Scale & UHManoa PV'!G29,"")) -> 8.585 | D30: =IF($C$2="Utility-Scale",'Utility Scale Estimates'!E23,IF($C$2="Commercial",'Commercial Scale & UHManoa PV'!C29/1000,"")) -> 0.257 | E30: =IF($C$2="Utility-Scale",'Utility Scale Estimates'!F23,IF($C$2="Commercial",'Commercial Scale & UHManoa PV'!E29,"")) -> 2023 | F30: =IF($C$2="Utility-Scale",'Utility Scale Estimates'!G23,IF($C$2="Commercial",'Commercial Scale & UHManoa PV'!D29,"")) -> No
A31: No | B31: =IF($C$2="Utility-Scale",'Utility Scale Estimates'!B24,IF($C$2="Commercial",'Commercial Scale & UHManoa PV'!B30,"")) -> New Landscape Building | C31: =IF($C$2="Utility-Scale",'Utility Scale Estimates'!C24,IF($C$2="Commercial",'Commercial Scale & UHManoa PV'!G30,"")) -> 8.585 | D31: =IF($C$2="Utility-Scale",'Utility Scale Estimates'!E24,IF($C$2="Commercial",'Commercial Scale & UHManoa PV'!C30/1000,"")) -> 0.105 | E31: =IF($C$2="Utility-Scale",'Utility Scale Estimates'!F24,IF($C$2="Commercial",'Commercial Scale & UHManoa PV'!E30,"")) -> 2023 | F31: =IF($C$2="Utility-Scale",'Utility Scale Estimates'!G24,IF($C$2="Commercial",'Commercial Scale & UHManoa PV'!D30,"")) -> No
A32: Yes | B32: =IF($C$2="Utility-Scale",'Utility Scale Estimates'!B25,IF($C$2="Commercial",'Commercial Scale & UHManoa PV'!B31,"")) -> Lower Campus Parking Phase 1 [Raised] | C32: =IF($C$2="Utility-Scale",'Utility Scale Estimates'!C25,IF($C$2="Commercial",'Commercial Scale & UHManoa PV'!G31,"")) -> 11.11 | D32: =IF($C$2="Utility-Scale",'Utility Scale Estimates'!E25,IF($C$2="Commercial",'Commercial Scale & UHManoa PV'!C31/1000,"")) -> 1.922 | E32: =IF($C$2="Utility-Scale",'Utility Scale Estimates'!F25,IF($C$2="Commercial",'Commercial Scale & UHManoa PV'!E31,"")) -> 2023 | F32: =IF($C$2="Utility-Scale",'Utility Scale Estimates'!G25,IF($C$2="Commercial",'Commercial Scale & UHManoa PV'!D31,"")) -> No
A33: Yes | B33: =IF($C$2="Utility-Scale",'Utility Scale Estimates'!B26,IF($C$2="Commercial",'Commercial Scale & UHManoa PV'!B32,"")) -> PV Canopy Transportation Services [Raised] | C33: =IF($C$2="Utility-Scale",'Utility Scale Estimates'!C26,IF($C$2="Commercial",'Commercial Scale & UHManoa PV'!G32,"")) -> 11.11 | D33: =IF($C$2="Utility-Scale",'Utility Scale Estimates'!E26,IF($C$2="Commercial",'Commercial Scale & UHManoa PV'!C32/1000,"")) -> 0.23 | E33: =IF($C$2="Utility-Scale",'Utility Scale Estimates'!F26,IF($C$2="Commercial",'Commercial Scale & UHManoa PV'!E32,"")) -> 2023 | F33: =IF($C$2="Utility-Scale",'Utility Scale Estimates'!G26,IF($C$2="Commercial",'Commercial Scale & UHManoa PV'!D32,"")) -> No
A34: No | B34: =IF($C$2="Utility-Scale",'Utility Scale Estimates'!B27,IF($C$2="Commercial",'Commercial Scale & UHManoa PV'!B33,"")) -> Gilmore Mechanical Building | C34: =IF($C$2="Utility-Scale",'Utility Scale Estimates'!C27,IF($C$2="Commercial",'Commercial Scale & UHManoa PV'!G33,"")) -> 0.8585 | D34: =IF($C$2="Utility-Scale",'Utility Scale Estimates'!E27,IF($C$2="Commercial",'Commercial Scale & UHManoa PV'!C33/1000,"")) -> 0.24 | E34: =IF($C$2="Utility-Scale",'Utility Scale Estimates'!F27,IF($C$2="Commercial",'Commercial Scale & UHManoa PV'!E33,"")) -> 2024 | F34: =IF($C$2="Utility-Scale",'Utility Scale Estimates'!G27,IF($C$2="Commercial",'Commercial Scale & UHManoa PV'!D33,"")) -> No
A35: No | B35: =IF($C$2="Utility-Scale",'Utility Scale Estimates'!B28,IF($C$2="Commercial",'Commercial Scale & UHManoa PV'!B34,"")) -> Queen Liliuokalani Center | C35: =IF($C$2="Utility-Scale",'Utility Scale Estimates'!C28,IF($C$2="Commercial",'Commercial Scale & UHManoa PV'!G34,"")) -> 8.08 | D35: =IF($C$2="Utility-Scale",'Utility Scale Estimates'!E28,IF($C$2="Commercial",'Commercial Scale & UHManoa PV'!C34/1000,"")) -> 0.061 | E35: =IF($C$2="Utility-Scale",'Utility Scale Estimates'!F28,IF($C$2="Commercial",'Commercial Scale & UHManoa PV'!E34,"")) -> 2024 | F35: =IF($C$2="Utility-Scale",'Utility Scale Estimates'!G28,IF($C$2="Commercial",'Commercial Scale & UHManoa PV'!D34,"")) -> No
A36: No | B36: =IF($C$2="Utility-Scale",'Utility Scale Estimates'!B29,IF($C$2="Commercial",'Commercial Scale & UHManoa PV'!B35,"")) -> Gilmore Hall | C36: =IF($C$2="Utility-Scale",'Utility Scale Estimates'!C29,IF($C$2="Commercial",'Commercial Scale & UHManoa PV'!G35,"")) -> 8.585 | D36: =IF($C$2="Utility-Scale",'Utility Scale Estimates'!E29,IF($C$2="Commercial",'Commercial Scale & UHManoa PV'!C35/1000,"")) -> 0.057 | E36: =IF($C$2="Utility-Scale",'Utility Scale Estimates'!F29,IF($C$2="Commercial",'Commercial Scale & UHManoa PV'!E35,"")) -> 2024 | F36: =IF($C$2="Utility-Scale",'Utility Scale Estimates'!G29,IF($C$2="Commercial",'Commercial Scale & UHManoa PV'!D35,"")) -> No
A37: Yes | B37: =IF($C$2="Utility-Scale",'Utility Scale Estimates'!B30,IF($C$2="Commercial",'Commercial Scale & UHManoa PV'!B36,"")) -> Biomed Parking Canopy [Raised] | C37: =IF($C$2="Utility-Scale",'Utility Scale Estimates'!C30,IF($C$2="Commercial",'Commercial Scale & UHManoa PV'!G36,"")) -> 11.11 | D37: =IF($C$2="Utility-Scale",'Utility Scale Estimates'!E30,IF($C$2="Commercial",'Commercial Scale & UHManoa PV'!C36/1000,"")) -> 0.783 | E37: =IF($C$2="Utility-Scale",'Utility Scale Estimates'!F30,IF($C$2="Commercial",'Commercial Scale & UHManoa PV'!E36,"")) -> 2024 | F37: =IF($C$2="Utility-Scale",'Utility Scale Estimates'!G30,IF($C$2="Commercial",'Commercial Scale & UHManoa PV'!D36,"")) -> No
... A40: No | B40: =IF($C$2="Utility-Scale",'Utility Scale Estimates'!B33,IF($C$2="Commercial",'Commercial Scale & UHManoa PV'!B39,"")) -> Makena State Park | C40: =IF($C$2="Utility-Scale",'Utility Scale Estimates'!C33,IF($C$2="Commercial",'Commercial Scale & UHManoa PV'!G39,"")) -> 7.27861 | D40: =IF($C$2="Utility-Scale",'Utility Scale Estimates'!E33,IF($C$2="Commercial",'Commercial Scale & UHManoa PV'!C39/1000,"")) -> 0.01 | E40: =IF($C$2="Utility-Scale",'Utility Scale Estimates'!F33,IF($C$2="Commercial",'Commercial Scale & UHManoa PV'!E39,"")) -> 2023 | F40: =IF($C$2="Utility-Scale",'Utility Scale Estimates'!G33,IF($C$2="Commercial",'Commercial Scale & UHManoa PV'!D39,"")) -> Yes

Sheet Utility Scale Estimates
A1: Include in Calculation | B1: Project Costs are aggregated (PV & Battery together) Some projects may have different sized batteries | C1: $ / W (Input Dependent Cells) | D1: $/W PV & BESS | E1: Installation Size (MW) | F1: Year Installed | G1: Storage Included | H1: $/W BESS | I1: $/W PV
A2: No | B2: HECO IGP Modelling Assumptions for Moloka‘i | C2: =IF('Cost Calculator'!$C$3="PV",I2,IF('Cost Calculator'!$C$3="PV + BESS",D2,H2)) -> 3.3764383 | D2: ='HECO Estimates'!D15 -> 3.3764383 | E2: Per MW Estimate | F2: Estimate from 2023 | G2: Per MW Estimate | H2: ='HECO Estimates'!D6 -> 0.92159965 | I2: ='HECO Estimates'!D2 -> 2.4548386
A3: No | B3: NREL National High Cost Estimate (Battery & PV Separate) | C3: =IF('Cost Calculator'!$C$3="PV",I3,IF('Cost Calculator'!$C$3="PV + BESS",D3,H3)) -> 2.121 | D3: =SUM(Estimate_8!B2,Estimate_8!B6) -> 2.121 | E3: Per MW Estimate | F3: Estimate from 2022 | G3: Per MW Estimate | H3: =Estimate_8!B6 -> 0.976 | I3: =Estimate_8!B2 -> 1.145
A4: Yes | B4: LBNL High End (Battery & PV Separate) | C4: =IF('Cost Calculator'!$C$3="PV",I4,IF('Cost Calculator'!$C$3="PV + BESS",D4,H4)) -> 2.3612 | D4: =SUM(H4,I4) -> 2.3612 | E4: Per MW Estimate | F4: Estimate from 2022 | G4: Per MW Estimate | H4: =Estimate_9!B10 -> 1.2812 | I4: =Estimate_9!B2 -> 1.08
A5: No | B5: LBNL Low End (Battery & PV Separate) | C5: =IF('Cost Calculator'!$C$3="PV",I5,IF('Cost Calculator'!$C$3="PV + BESS",D5,H5)) -> 2.93968 | D5: =SUM(H5,I5) -> 2.93968 | E5: Per MW Estimate | F5: Estimate from 2022 | G5: Per MW Estimate | H5: =Estimate_9!B11 -> 1.43968 | I5: =Estimate_9!B3 -> 1.5
A6: Yes | B6: LBNL Hawaii Prices (Battery & PV Separate) | C6: =IF('Cost Calculator'!$C$3="PV",I6,IF('Cost Calculator'!$C$3="PV + BESS",D6,H6)) -> 4.67968 | D6: =SUM(H6,I6) -> 4.67968 | E6: Per MW Estimate | F6: Estimate from 2018 | G6: Per MW Estimate | H6: =Estimate_9!B11 -> 1.43968 | I6: =Estimate_9!B4 -> 3.24
A7: No | B7: KIUC Anahola, Utility Scale, (12 MW, 6 MW Battery) | C7: =IF('Cost Calculator'!$C$3="PV",I7,IF('Cost Calculator'!$C$3="PV + BESS",D7,H7)) -> 5.0321526 | D7: =Estimate_3!B11 -> 5.0321526 | E7: 12 | F7: 2020 | G7: 6MWh | H7: =Estimate_3!B10 -> 2.4416667 | I7: =Estimate_3!B9 -> 3.6588665
A8: No | B8: KIUC Koloa, Utility Scale, (12 MW, 6 MW Battery) | C8: =IF('Cost Calculator'!$C$3="PV",I8,IF('Cost Calculator'!$C$3="PV + BESS",D8,H8)) -> 3.4333333 | D8: =Estimate_4!B3 -> 3.4333333 | E8: 12 | F8: 2016 | G8: 6MWh | H8: - | I8: -
A9: No | B9: Waiawa Phase 1, Utility Scale, (36 MW, 144 MWh) | C9: =IF('Cost Calculator'!$C$3="PV",I9,IF('Cost Calculator'!$C$3="PV + BESS",D9,H9)) -> 1.7027778 | D9: =Estimate_1!B3 -> 1.7027778 | E9: 36 | F9: 2023 | G9: 144MWh | H9: - | I9: -
A10: No | B10: AES West O‘ahu , Utility-Scale, (12.5MW, 50 MWh) | C10: =IF('Cost Calculator'!$C$3="PV",I10,IF('Cost Calculator'!$C$3="PV + BESS",D10,H10)) -> 3.68 | D10: =Estimate_2!B3 -> 3.68 | E10: 12.5 | F10: 2023 | G10: 50MWh | H10: - | I10: -
A11: Yes | B11: AES Kuihelani, Utility Scale, (60 MW, 240 MWh) | C11: =IF('Cost Calculator'!$C$3="PV",I11,IF('Cost Calculator'!$C$3="PV + BESS",D11,H11)) -> 1.1333333 | D11: =Estimate_6!B4 -> 1.1333333 | E11: 60 | F11: Anticipated 2024 | G11: 240MWh | H11: - | I11: -
A12: No | B12: Moloka‘i CBRE Projects (2), Pala'au & Kualapu'u, (2.45 MW, 11.1 MWh) | C12: =IF('Cost Calculator'!$C$3="PV",I12,IF('Cost Calculator'!$C$3="PV + BESS",D12,H12)) -> 8.0816327 | D12: =Estimate_7!B7 -> 8.0816327 | E12: 2.45 | F12: Anticipated 2025 | G12: 11.1MWh | H12: - | I12: -
A13: - | B13: - | C13: =IF('Cost Calculator'!$C$3="PV",I13,IF('Cost Calculator'!$C$3="PV + BESS",D13,H13)) -> - | D13: - | E13: - | F13: - | G13: - | H13: - | I13: -
A14: - | B14: - | C14: =IF('Cost Calculator'!$C$3="PV",I14,IF('Cost Calculator'!$C$3="PV + BESS",D14,H14)) -> - | D14: - | E14: - | F14: - | G14: - | H14: - | I14: -
A15: - | B15: - | C15: =IF('Cost Calculator'!$C$3="PV",I15,IF('Cost Calculator'!$C$3="PV + BESS",D15,H15)) -> - | D15: - | E15: - | F15: - | G15: - | H15: - | I15: -
A16: - | B16: - | C16: =IF('Cost Calculator'!$C$3="PV",I16,IF('Cost Calculator'!$C$3="PV + BESS",D16,H16)) -> - | D16: - | E16: - | F16: - | G16: - | H16: - | I16: -
A17: - | B17: - | C17: =IF('Cost Calculator'!$C$3="PV",I17,IF('Cost Calculator'!$C$3="PV + BESS",D17,H17)) -> - | D17: - | E17: - | F17: - | G17: - | H17: - | I17: -
A18: - | B18: - | C18: =IF('Cost Calculator'!$C$3="PV",I18,IF('Cost Calculator'!$C$3="PV + BESS",D18,H18)) -> - | D18: - | E18: - | F18: - | G18: - | H18: - | I18: -
A19: - | B19: - | C19: =IF('Cost Calculator'!$C$3="PV",I19,IF('Cost Calculator'!$C$3="PV + BESS",D19,H19)) -> - | D19: - | E19: - | F19: - | G19: - | H19: - | I19: -
A20: - | B20: - | C20: =IF('Cost Calculator'!$C$3="PV",I20,IF('Cost Calculator'!$C$3="PV + BESS",D20,H20)) -> - | D20: - | E20: - | F20: - | G20: - | H20: - | I20: -
A21: - | B21: - | C21: =IF('Cost Calculator'!$C$3="PV",I21,IF('Cost Calculator'!$C$3="PV + BESS",D21,H21)) -> - | D21: - | E21: - | F21: - | G21: - | H21: - | I21: -
A22: - | B22: - | C22: =IF('Cost Calculator'!$C$3="PV",I22,IF('Cost Calculator'!$C$3="PV + BESS",D22,H22)) -> - | D22: - | E22: - | F22: - | G22: - | H22: - | I22: -
A23: - | B23: - | C23: =IF('Cost Calculator'!$C$3="PV",I23,IF('Cost Calculator'!$C$3="PV + BESS",D23,H23)) -> - | D23: - | E23: - | F23: - | G23: - | H23: - | I23: -
A24: - | B24: - | C24: =IF('Cost Calculator'!$C$3="PV",I24,IF('Cost Calculator'!$C$3="PV + BESS",D24,H24)) -> - | D24: - | E24: - | F24: - | G24: - | H24: - | I24: -
... A92: - | B92: - | C92: =IF('Cost Calculator'!$C$3="PV",I92,IF('Cost Calculator'!$C$3="PV + BESS",D92,H92)) -> - | D92: - | E92: - | F92: - | G92: - | H92: - | I92: -

Sheet Commercial Scale & UHManoa PV
B2: Averages from From Below Data: | C2: < 100 kw | D2: >= 100 kw | E2: *** None of these have storage listed, but NEED to verify for sure!
B3: Average Project cost ($/W) PV Only | C3: =AVERAGE(H8:H65) -> 5.5693151 | D3: =AVERAGE(I8:I65) -> 8.131126
B4: Average Project cost ($/W) PV Plus | C4: =IFERROR(AVERAGE(J8:J65),"") -> 7.27861 | D4: =IFERROR(AVERAGE(K8:K65),"")
H5: PV Only | J5: PV + BESS
C6: PV Capacity (kw) | D6: Storage Included? | E6: Date Activated | F6: Cost ($) | G6: $/W | H6: $/W Under 100 kw | I6: $/W over KW | J6: $/W Under 100 kw | K6: $/W over KW
A8: UH Manoa Existing or Under Development | B8: Gateway House | C8: 29 | D8: No | E8: 2023 | F8: 103222 | G8: =F8/(C8*1000) -> 3.5593793 | H8: =IF(AND(C8<100, D8="No"),G8,"") -> 3.5593793 | I8: =IF(AND(C8>=100, D8="No"),G8,"") | J8: =IF(AND(C8<100, D8="Yes"),G8,"") | K8: =IF(AND(C8>=100, D8="Yes"),G8,"")
B9: Frear Hall | C9: 47 | D9: No | E9: 2023 | F9: 166145 | G9: =F9/(C9*1000) -> 3.535 | H9: =IF(AND(C9<100, D9="No"),G9,"") -> 3.535 | I9: =IF(AND(C9>=100, D9="No"),G9,"") | J9: =IF(AND(C9<100, D9="Yes"),G9,"") | K9: =IF(AND(C9>=100, D9="Yes"),G9,"")
B10: Gyms 1&2 | C10: 324 | D10: No | E10: 2023 | F10: 1636200 | G10: =F10/(C10*1000) -> 5.05 | H10: =IF(AND(C10<100, D10="No"),G10,"") | I10: =IF(AND(C10>=100, D10="No"),G10,"") -> 5.05 | J10: =IF(AND(C10<100, D10="Yes"),G10,"") | K10: =IF(AND(C10>=100, D10="Yes"),G10,"")
B11: John Burns Hall | C11: 180 | D11: No | E11: 2011 | F11: 909000 | G11: =F11/(C11*1000) -> 5.05 | H11: =IF(AND(C11<100, D11="No"),G11,"") | I11: =IF(AND(C11>=100, D11="No"),G11,"") -> 5.05 | J11: =IF(AND(C11<100, D11="Yes"),G11,"") | K11: =IF(AND(C11>=100, D11="Yes"),G11,"")
B12: Gartley Hall | C12: 45 | D12: No | E12: 2014 | F12: 227250 | G12: =F12/(C12*1000) -> 5.05 | H12: =IF(AND(C12<100, D12="No"),G12,"") -> 5.05 | I12: =IF(AND(C12>=100, D12="No"),G12,"") | J12: =IF(AND(C12<100, D12="Yes"),G12,"") | K12: =IF(AND(C12>=100, D12="Yes"),G12,"")
B13: Holmes Hall | C13: 8.45 | D13: No | E13: 2013 | F13: 42673 | G13: =F13/(C13*1000) -> 5.0500592 | H13: =IF(AND(C13<100, D13="No"),G13,"") -> 5.0500592 | I13: =IF(AND(C13>=100, D13="No"),G13,"") | J13: =IF(AND(C13<100, D13="Yes"),G13,"") | K13: =IF(AND(C13>=100, D13="Yes"),G13,"")
B14: Sinclair Library | C14: 30.5 | D14: No | E14: 2012 | F14: 159075 | G14: =F14/(C14*1000) -> 5.2155738 | H14: =IF(AND(C14<100, D14="No"),G14,"") -> 5.2155738 | I14: =IF(AND(C14>=100, D14="No"),G14,"") | J14: =IF(AND(C14<100, D14="Yes"),G14,"") | K14: =IF(AND(C14>=100, D14="Yes"),G14,"")
B15: Warrior Recreation | C15: 33 | D15: No | E15: 2013 | F15: 166650 | G15: =F15/(C15*1000) -> 5.05 | H15: =IF(AND(C15<100, D15="No"),G15,"") -> 5.05 | I15: =IF(AND(C15>=100, D15="No"),G15,"") | J15: =IF(AND(C15<100, D15="Yes"),G15,"") | K15: =IF(AND(C15>=100, D15="Yes"),G15,"")
B16: FROG Buildings | C16: 16.12 | D16: No | E16: 2018 | F16: 81406 | G16: =F16/(C16*1000) -> 5.05 | H16: =IF(AND(C16<100, D16="No"),G16,"") -> 5.05 | I16: =IF(AND(C16>=100, D16="No"),G16,"") | J16: =IF(AND(C16<100, D16="Yes"),G16,"") | K16: =IF(AND(C16>=100, D16="Yes"),G16,"")
B17: PBRC | C17: 36.19 | D17: No | E17: 2012 | F17: 182760 | G17: =F17/(C17*1000) -> 5.0500138 | H17: =IF(AND(C17<100, D17="No"),G17,"") -> 5.0500138 | I17: =IF(AND(C17>=100, D17="No"),G17,"") | J17: =IF(AND(C17<100, D17="Yes"),G17,"") | K17: =IF(AND(C17>=100, D17="Yes"),G17,"")
B18: Dance Building | C18: 11 | D18: No | E18: 2023 | F18: 55651 | G18: =F18/(C18*1000) -> 5.0591818 | H18: =IF(AND(C18<100, D18="No"),G18,"") -> 5.0591818 | I18: =IF(AND(C18>=100, D18="No"),G18,"") | J18: =IF(AND(C18<100, D18="Yes"),G18,"") | K18: =IF(AND(C18>=100, D18="Yes"),G18,"")
B19: Cancer Center (Freezer Facility) | C19: 15 | D19: No | E19: 2023 | F19: 74235 | G19: =F19/(C19*1000) -> 4.949 | H19: =IF(AND(C19<100, D19="No"),G19,"") -> 4.949 | I19: =IF(AND(C19>=100, D19="No"),G19,"") | J19: =IF(AND(C19<100, D19="Yes"),G19,"") | K19: =IF(AND(C19>=100, D19="Yes"),G19,"")
B20: Parking Permit Zone 1 [Raised] | C20: 335 | D20: No | E20: 2023 | F20: 2706800 | G20: =F20/(C20*1000) -> 8.08 | H20: =IF(AND(C20<100, D20="No"),G20,"") | I20: =IF(AND(C20>=100, D20="No"),G20,"") -> 8.08 | J20: =IF(AND(C20<100, D20="Yes"),G20,"") | K20: =IF(AND(C20>=100, D20="Yes"),G20,"")
... B32: PV Canopy Transportation Services [Raised] | C32: 230 | D32: No | E32: 2023 | F32: 2555300 | G32: =F32/(C32*1000) -> 11.11 | H32: =IF(AND(C32<100, D32="No"),G32,"") | I32: =IF(AND(C32>=100, D32="No"),G32,"") -> 11.11 | J32: =IF(AND(C32<100, D32="Yes"),G32,"") | K32: =IF(AND(C32>=100, D32="Yes"),G32,"")
A33: UH Manoa, 2024 Planned | B33: Gilmore Mechanical Building | C33: 240 | D33: No | E33: 2024 | F33: 206040 | G33: =F33/(C33*1000) -> 0.8585 | H33: =IF(AND(C33<100, D33="No"),G33,"") | I33: =IF(AND(C33>=100, D33="No"),G33,"") -> 0.8585 | J33: =IF(AND(C33<100, D33="Yes"),G33,"") | K33: =IF(AND(C33>=100, D33="Yes"),G33,"")
B34: Queen Liliuokalani Center | C34: 61 | D34: No | E34: 2024 | F34: 492880 | G34: =F34/(C34*1000) -> 8.08 | H34: =IF(AND(C34<100, D34="No"),G34,"") -> 8.08 | I34: =IF(AND(C34>=100, D34="No"),G34,"") | J34: =IF(AND(C34<100, D34="Yes"),G34,"") | K34: =IF(AND(C34>=100, D34="Yes"),G34,"")
B35: Gilmore Hall | C35: 57 | D35: No | E35: 2024 | F35: 489345 | G35: =F35/(C35*1000) -> 8.585 | H35: =IF(AND(C35<100, D35="No"),G35,"") -> 8.585 | I35: =IF(AND(C35>=100, D35="No"),G35,"") | J35: =IF(AND(C35<100, D35="Yes"),G35,"") | K35: =IF(AND(C35>=100, D35="Yes"),G35,"")
B36: Biomed Parking Canopy [Raised] | C36: 783 | D36: No | E36: 2024 | F36: 8699130 | G36: =F36/(C36*1000) -> 11.11 | H36: =IF(AND(C36<100, D36="No"),G36,"") | I36: =IF(AND(C36>=100, D36="No"),G36,"") -> 11.11 | J36: =IF(AND(C36<100, D36="Yes"),G36,"") | K36: =IF(AND(C36>=100, D36="Yes"),G36,"")
B37: Parking Permit Zone 17 - Music Complex [Raised] | C37: 422 | D37: No | E37: 2024 | F37: 4606610 | G37: =F37/(C37*1000) -> 10.916137 | H37: =IF(AND(C37<100, D37="No"),G37,"") | I37: =IF(AND(C37>=100, D37="No"),G37,"") -> 10.916137 | J37: =IF(AND(C37<100, D37="Yes"),G37,"") | K37: =IF(AND(C37>=100, D37="Yes"),G37,"")
A38: State Procured | B38: YCA Hilo Gym Solar | C38: 57 | D38: No | E38: 2023 | F38: 207814 | G38: =F38/(C38*1000) -> 3.6458596 | H38: =IF(AND(C38<100, D38="No"),G38,"") -> 3.6458596 | I38: =IF(AND(C38>=100, D38="No"),G38,"") | J38: =IF(AND(C38<100, D38="Yes"),G38,"") | K38: YCA Hilo Gym Solar
B39: Makena State Park | C39: 10 | D39: Yes | E39: 2023 | F39: 72786.1 | G39: =F39/(C39*1000) -> 7.27861 | H39: =IF(AND(C39<100, D39="No"),G39,"") | I39: =IF(AND(C39>=100, D39="No"),G39,"") | J39: =IF(AND(C39<100, D39="Yes"),G39,"") -> 7.27861 | K39: Makena State Park

Sheet Cost Breakdowns
B2: Commercial Scale (1MW) | C2: PV Plus Battery (Co-located, DC Coupled) | F2: PV Only | I2: Battery Only
B3: Bottom Up Cost Estimate | C3: ($/MW PV, .6MW 2.4MWh Battery) | D3: ($/W, with 4 hour .6W storage) | E3: % of Total | F3: ($/MW) | G3: ($/W) | H3: % of Total | I3: ($/.6MW) | J3: $/W | K3: % of Total
B4: Engineering, Procurement, Construction /Developer Net Profit | C4: 164 | D4: =C4/1000 -> 0.164 | E4: =D4/$D$20 -> 0.074174582 | F4: 126 | G4: =F4/1000 -> 0.126 | H4: =G4/$G$20 -> 0.075044669 | I4: 52 | J4: =I4/0.6/1000 -> 0.086666667 | K4: =J4/$J$20 -> 0.049713193
B5: Developer Overhead | C5: 58 | D5: =C5/1000 -> 0.058 | E5: =D5/$D$20 -> 0.026232474 | F5: 352 | G5: =F5/1000 -> 0.352 | H5: =G5/$G$20 -> 0.2096486 | I5: 57 | J5: =I5/0.6/1000 -> 0.095 | K5: =J5/$J$20 -> 0.054493308
B6: Contingency | C6: 58 | D6: =C6/1000 -> 0.058 | E6: =D6/$D$20 -> 0.026232474 | F6: 47 | G6: =F6/1000 -> 0.047 | H6: =G6/$G$20 -> 0.027992853 | I6: 38 | J6: =I6/0.6/1000 -> 0.063333333 | K6: =J6/$J$20 -> 0.036328872
B7: Transmission Line | D7: =C7/1000 -> 0 | E7: =D7/$D$20 -> 0 | G7: =F7/1000 -> 0 | H7: =G7/$G$20 -> 0 | J7: =I7/0.6/1000 -> 0 | K7: =J7/$J$20 -> 0
B8: Interconnection Fee | C8: 28 | D8: =C8/1000 -> 0.028 | E8: =D8/$D$20 -> 0.012663953 | F8: 28 | G8: =F8/1000 -> 0.028 | H8: =G8/$G$20 -> 0.016676593 | I8: 28 | J8: =I8/0.6/1000 -> 0.046666667 | K8: =J8/$J$20 -> 0.026768642
B9: Permitting Fee | C9: 7 | D9: =C9/1000 -> 0.007 | E9: =D9/$D$20 -> 0.0031659882 | F9: 7 | G9: =F9/1000 -> 0.007 | H9: =G9/$G$20 -> 0.0041691483 | I9: 7 | J9: =I9/0.6/1000 -> 0.011666667 | K9: =J9/$J$20 -> 0.0066921606
B10: Land Acquisition | D10: =C10/1000 -> 0 | E10: =D10/$D$20 -> 0 | G10: =F10/1000 -> 0 | H10: =G10/$G$20 -> 0 | J10: =I10/0.6/1000 -> 0 | K10: =J10/$J$20 -> 0
B11: Sale Tax | C11: 94 | D11: =C11/1000 -> 0.094 | E11: =D11/$D$20 -> 0.042514699 | F11: 54 | G11: =F11/1000 -> 0.054 | H11: =G11/$G$20 -> 0.032162001 | I11: 50 | J11: =I11/0.6/1000 -> 0.083333333 | K11: =J11/$J$20 -> 0.047801147
B12: EPC Overhead | C12: 178 | D12: =C12/1000 -> 0.178 | E12: =D12/$D$20 -> 0.080506558 | F12: 97 | G12: =F12/1000 -> 0.097 | H12: =G12/$G$20 -> 0.057772484 | I12: 97 | K12: =J12/$J$20 -> 0
B13: Install labor & Equipment | C13: 315 | D13: =C13/1000 -> 0.315 | E13: =D13/$D$20 -> 0.14246947 | F13: 188 | G13: =F13/1000 -> 0.188 | H13: =G13/$G$20 -> 0.11197141 | I13: 151 | J13: =I13/0.6/1000 -> 0.25166667 | K13: =J13/$J$20 -> 0.14435946
B14: Electrical BOS | C14: 221 | D14: =C14/1000 -> 0.221 | E14: =D14/$D$20 -> 0.099954772 | F14: 186 | G14: =F14/1000 -> 0.186 | H14: =G14/$G$20 -> 0.11078023 | I14: 106 | J14: =I14/0.6/1000 -> 0.17666667 | K14: =J14/$J$20 -> 0.10133843
B15: Structural BOS | C15: 185 | D15: =C15/1000 -> 0.185 | E15: =D15/$D$20 -> 0.083672546 | F15: 117 | G15: =F15/1000 -> 0.117 | H15: =G15/$G$20 -> 0.069684336 | I15: 60 | J15: =I15/0.6/1000 -> 0.1 | K15: =J15/$J$20 -> 0.057361377
B16: Bidirectional Inverter | C16: 36 | D16: =C16/1000 -> 0.036 | E16: =D16/$D$20 -> 0.016282225 | G16: =F16/1000 -> 0 | H16: =G16/$G$20 -> 0 | I16: 36 | J16: =I16/0.6/1000 -> 0.06 | K16: =J16/$J$20 -> 0.034416826
B17: Solar Inverter | D17: =C17/1000 -> 0 | E17: =D17/$D$20 -> 0 | F17: 71 | G17: =F17/1000 -> 0.071 | H17: =G17/$G$20 -> 0.042287076 | J17: =I17/0.6/1000 -> 0 | K17: =J17/$J$20 -> 0
B18: Lithium Ion Battery | C18: 461 | D18: =C18/1000 -> 0.461 | E18: =D18/$D$20 -> 0.20850294 | G18: =F18/1000 -> 0 | H18: =G18/$G$20 -> 0 | I18: 461 | J18: =I18/0.6/1000 -> 0.76833333 | K18: =J18/$J$20 -> 0.44072658
B19: PV Module | C19: 406 | D19: =C19/1000 -> 0.406 | E19: =D19/$D$20 -> 0.18362732 | F19: 406 | G19: =F19/1000 -> 0.406 | H19: =G19/$G$20 -> 0.2418106 | J19: =I19/0.6/1000 -> 0 | K19: =J19/$J$20 -> 0
B20: Total | C20: =SUM(C4:C19) -> 2211 | D20: =C20/1000 -> 2.211 | E20: =D20/$D$20 -> 1 | F20: =SUM(F4:F19) -> 1679 | G20: =F20/1000 -> 1.679 | H20: =G20/$G$20 -> 1 | I20: 1122 | J20: =SUM(J4:J19) -> 1.7433333 | K20: =J20/$J$20 -> 1
B24: Utility Scale (60 MW) | C24: PV Plus Battery (Co-located, AC coupled system) | F24: PV Only | I24: Battery Only
B25: Bottom Up Cost Estimate | C25: ($/W) | E25: % of Total | F25: ($/W) | H25: % of Total | I25: ($/kW) | J25: $/kWh | K25: % of Total
B26: Engineering, Procurement, Construction /Developer Net Profit | C26: 0.08 | E26: =C26/$C$42 -> 0.04 | I26: =J26*4 -> 176 | J26: 44 | K26: =I26/$I$42 -> 0.11548556
B27: Developer Overhead | C27: 0.06 | E27: =C27/$C$42 -> 0.03 | I27: =J27*4 -> 60 | J27: 15 | K27: =I27/$I$42 -> 0.039370079
B28: Contingency | C28: 0.05 | E28: =C28/$C$42 -> 0.025 | I28: =J28*4 -> 0 | J28: 0 | K28: =I28/$I$42 -> 0
B29: Transmission Line | C29: 0.02 | E29: =C29/$C$42 -> 0.01 | I29: =J29*4 -> 0 | J29: 0 | K29: =I29/$I$42 -> 0
B30: Interconnection Fee | C30: 0.03 | E30: =C30/$C$42 -> 0.015 | I30: =J30*4 -> 0 | J30: 0 | K30: =I30/$I$42 -> 0
B31: Permitting Fee | E31: =C31/$C$42 -> 0 | I31: =J31*4 -> 0 | J31: 0 | K31: =I31/$I$42 -> 0
B32: Land Acquisition | E32: =C32/$C$42 -> 0 | I32: =J32*4 -> 0 | J32: 0 | K32: =I32/$I$42 -> 0
B33: Sale Tax | C33: 0.09 | E33: =C33/$C$42 -> 0.045 | I33: =J33*4 -> 60 | J33: 15 | K33: =I33/$I$42 -> 0.039370079
B34: EPC Overhead | C34: 0.07 | E34: =C34/$C$42 -> 0.035 | I34: =J34*4 -> 0 | J34: 0 | K34: =I34/$I$42 -> 0
B35: Install labor & Equipment | C35: 0.16 | E35: =C35/$C$42 -> 0.08 | I35: =J35*4 -> 112 | J35: 28 | K35: =I35/$I$42 -> 0.073490814
B36: Electrical BOS | C36: 0.18 | E36: =C36/$C$42 -> 0.09 | I36: =J36*4 -> 96 | J36: 24 | K36: =I36/$I$42 -> 0.062992126
B37: Structural BOS | C37: 0.19 | E37: =C37/$C$42 -> 0.095 | I37: =J37*4 -> 208 | J37: 52 | K37: =I37/$I$42 -> 0.13648294
B38: Bidirectional Inverter | C38: 0.04 | E38: =C38/$C$42 -> 0.02 | I38: =J38*4 -> 60 | J38: 15 | K38: =I38/$I$42 -> 0.039370079
B39: Solar Inverter | C39: 0.07 | E39: =C39/$C$42 -> 0.035 | I39: =J39*4 -> 0 | J39: 0 | K39: =I39/$I$42 -> 0
B40: Lithium Ion Battery | C40: 0.43 | E40: =C40/$C$42 -> 0.215 | I40: =J40*4 -> 752 | J40: 188 | K40: =I40/$I$42 -> 0.49343832
B41: PV Module | C41: 0.53 | E41: =C41/$C$42 -> 0.265 | I41: =J41*4 -> 0 | J41: 0 | K41: =I41/$I$42 -> 0
B42: Total | C42: =SUM(C26:C41) -> 2 | E42: =C42/$C$42 -> 1 | I42: =SUM(I26:I41) -> 1524 | J42: =SUM(J26:J41) -> 381 | K42: =I42/$I$42 -> 1
B46: Residential Scale (1MW) | C46: PV Plus Battery (Co-located) | F46: PV Only | I46: Battery Only (5kW, 14kWh)
B47: Bottom Up Cost Estimate | C47: ($/ 6 kW) | D47: $/ W | E47: % of Total | F47: ($/ 6 kW) | G47: $/ W | H47: % of Total | I47: ($/ 6 kW) | J47: $/ W | K47: % of Total
...

Sheet Utility Scale Estimate Sheet
A1: Background Worksheet for Estimating Project Costs | C1: Method for Estimating Costs & Size | E1: Other Informaiton
A2: Waiawa Phase 1 | C2: * Based on Online Permit Values
A3: Project Cost | B3: 61300000
A4: $/W, with battery | B4: =B3/36000000 -> 1.7027778
A6: AES West Oahu | B6: Total Cost | C6: Value from Estimate provided through Environmental Impact Study
A7: Project Cost (High) | B7: =C7 -> 46000000 | C7: 46000000
A8: $/W, with storage | B8: =B7/12500000 -> 3.68
A10: KIUC ANAHOLA SOLAR PROJECT | C10: * Value from Estimate in Draft EIS
A11: Solar Costs | B11: 38585831
A12: Substation | B12: 7400000
A13: BESS | B13: 7500000
A14: Service Center | B14: 5400000
A15: Other Costs | B15: 1500000
A16: Total Costs | B16: =SUM(B11:B15) -> 60385831
A18: $/W, PV | B18: =(SUM(B12,B14,B15)/2+B11)/12500000 -> 3.6588665
A19: $/W Battery | B19: =(SUM(B12,B14,B15)/2+B13)/6000000 -> 2.4416667
A20: $/W Paired | B20: =B16/12000000 -> 5.0321526
A21: * Assumes all other costs split evenly between battery & solar
A23: KIUC KOLOA | C23: * Value from PUC Filing
A24: Total Project Costs | B24: 41200000
A25: $/W, with 2 hr storage | B25: =B24/12000000 -> 3.4333333
A27: HECO IGP Forecasted Costs (Moloka‘i, 2023) | B27: $/kW | C27: $/W | D27: $/W, Adjusted for Federal Tax | E27: O&M Cost per kW | F27: O&M Cost per W
A28: Paired Grid-Scale PV (Single axis tracking) | B28: 1472.9032 | C28: =B28/1000 -> 1.4729032 | D28: =C28/(1-0.4) -> 2.4548386 | E28: 42 | F28: =E28/1000 -> 0.042
A29: PV Grid Scale Single Axis Tracking (2023): | B29: 1632.254 | C29: =B29/1000 -> 1.632254 | D29: =C29/(1-0.4) -> 2.7204234 | E29: 28 | F29: =E29/1000 -> 0.028
A30: Commercial-Scale PV | B30: 1984.4393 | C30: =B30/1000 -> 1.9844393 | D30: =C30/(1-0.3-0.35) -> 5.6698264 | E30: 25 | F30: =E30/1000 -> 0.025
A31: Residential PV | B31: 2749.41 | C31: =B31/1000 -> 2.74941 | D31: =C31/(1-0.26-0.35) -> 7.0497693 | E31: 36 | F31: =E31/1000 -> 0.036
A32: Standalone Storage | B32: 645.11975 | C32: =B32/1000 -> 0.64511975 | D32: =C32/(1-0.3) -> 0.92159965 | E32: 36 | F32: =E32/1000 -> 0.036
A33: Standalone Storage (BOS) | B33: 320.38347 | C33: =B33/1000 -> 0.32038347 | D33: =C33/(1-0.3) -> 0.45769067
A34: Standalone Storage (Modules) | B34: 324.73628 | C34: =B34/1000 -> 0.32473628 | D34: =C34/(1-0.3) -> 0.46390898
A35: Commercial Scale Storage (2 hours) | B35: 1076.278 | C35: =B35/1000 -> 1.076278 | D35: =C35/(1-0.3) -> 1.53754
A36: Commercial Scale Storage (4 hours) | B36: 2152.556 | C36: =B36/1000 -> 2.152556 | D36: =C36/(1-0.3) -> 3.07508 | E36: 38 | F36: =E36/1000 -> 0.038
A37: Residential Storage (2 hours) | B37: 2903.6454 | C37: =B37/1000 -> 2.9036454 | D37: =C37/(1-0.3) -> 4.1480648 | E37: 38 | F37: =E37/1000 -> 0.038
A38: Residential Storage (4 hours) | B38: 5807.2907 | C38: =B38/1000 -> 5.8072907 | D38: =C38/(1-0.3) -> 8.2961296 | E38: 122 | F38: =E38/1000 -> 0.122
B39: 1472.9032 | C39: =B39/1000 -> 1.4729032 | D39: =C39/(1-0.3) -> 2.1041474 | E39: 122 | F39: =E39/1000 -> 0.122
A41: PV Plus Battery | C41: =SUM(C32,C28) -> 2.1180229 | D41: =SUM(D32,D28) -> 3.3764383
A43: AES Kuihelani | B43: Total Cost | C43: * Value from Estimate Permit Applications
A44: System Size: 60 MW, 240 MWh | B44: =SUM(C44:C46) -> 33072998 | C44: 6569498
A45: $/W with storage: | B45: =B44/60000000 -> 0.55121663 | C45: 203500
A46: ** More realistic - they have a quote of $68M in local economic expenditures, but I can't verify | B46: =68000000/60000000 -> 1.1333333 | C46: 26300000
A49: AES Breaks Ground on Hawaiʻi's Largest Solar Project: Kuihelani Solar Plus Storage on Maui | AES Hawai‘i (aes-hawaii.com)
...

Sheet Estimate_1
A1: Waiawa Phase 1 | B1: Total Cost | C1: * Based on Online Permit Values
A2: Project Cost | B2: 61300000
A3: $/W, with battery | B3: =B2/36000000 -> 1.7027778

Sheet Estimate_2
A1: AES West Oahu | B1: Total Cost | C1: Value from Estimate provided through Environmental Impact Study
A2: Project Cost (High) | B2: =C2 -> 46000000 | C2: 46000000
A3: $/W, with storage | B3: =B2/12500000 -> 3.68

Sheet Estimate_3
A1: KIUC ANAHOLA SOLAR PROJECT | C1: * Value from Estimate in Draft EIS
A2: Solar Costs | B2: 38585831
A3: Substation | B3: 7400000
A4: BESS | B4: 7500000
A5: Service Center | B5: 5400000
A6: Other Costs | B6: 1500000
A7: Total Costs | B7: =SUM(B2:B6) -> 60385831
A9: $/W, PV | B9: =(SUM(B3,B5,B6)/2+B2)/12500000 -> 3.6588665
A10: $/W Battery | B10: =(SUM(B3,B5,B6)/2+B4)/6000000 -> 2.4416667
A11: $/W Paired | B11: =B7/12000000 -> 5.0321526
A14: * Assumes all other costs split evenly between battery & solar

Sheet Estimate_4
A1: KIUC KOLOA | C1: * Value from PUC Filing
A2: Total Project Costs | B2: 41200000
A3: $/W, with 2 hr storage | B3: =B2/12000000 -> 3.4333333

Sheet HECO Estimates
A1: HECO IGP Forecasted Costs (Moloka‘i, 2023) | B1: $/kW | C1: $/W | D1: $/W, Adjusted for Federal Tax | E1: O&M Cost per kW | F1: O&M Cost per W
A2: Paired Grid-Scale PV (Single axis tracking) | B2: 1472.9032 | C2: =B2/1000 -> 1.4729032 | D2: =C2/(1-0.4) -> 2.4548386 | E2: 42 | F2: =E2/1000 -> 0.042
A3: PV Grid Scale Single Axis Tracking (2023): | B3: 1632.254 | C3: =B3/1000 -> 1.632254 | D3: =C3/(1-0.4) -> 2.7204234 | E3: 28 | F3: =E3/1000 -> 0.028
A4: Commercial-Scale PV | B4: 1984.4393 | C4: =B4/1000 -> 1.9844393 | D4: =C4/(1-0.3-0.35) -> 5.6698264 | E4: 25 | F4: =E4/1000 -> 0.025
A5: Residential PV | B5: 2749.41 | C5: =B5/1000 -> 2.74941 | D5: =C5/(1-0.26-0.35) -> 7.0497693 | E5: 36 | F5: =E5/1000 -> 0.036
A6: Standalone Storage | B6: 645.11975 | C6: =B6/1000 -> 0.64511975 | D6: =C6/(1-0.3) -> 0.92159965 | E6: 36 | F6: =E6/1000 -> 0.036
A7: Standalone Storage (BOS) | B7: 320.38347 | C7: =B7/1000 -> 0.32038347 | D7: =C7/(1-0.3) -> 0.45769067
A8: Standalone Storage (Modules) | B8: 324.73628 | C8: =B8/1000 -> 0.32473628 | D8: =C8/(1-0.3) -> 0.46390898
A9: Commercial Scale Storage (2 hours) | B9: 1076.278 | C9: =B9/1000 -> 1.076278 | D9: =C9/(1-0.3) -> 1.53754
